Workbook

Sheet Hoja1
A1: precompostaje
A2: largo | B2: ancho | C2: alto | D2: vol
A3: =5+3.6+1.7 -> 10.3 | B3: 0.643 | C3: 1.7 | D3: =A3*B3*C3 -> 11.25893
A4: camas | D4: vol
A5: =4.3*4 -> 17.2 | B5: 1.62 | C5: 0.425 | D5: =A5*B5*C5 -> 11.8422
A6: 4.3 | B6: 0.81 | C6: 0.425 | D6: =A6*B6*C6 -> 1.480275
A7: =SUM(A5:A6) -> 21.5 | B7: =SUM(B5:B6) -> 2.43 | C7: =SUM(C5:C6) -> 0.85 | D7: =SUM(D5:D6) -> 13.322475
A11: Worm density
A13: Densidad usada en estudio short term | B13: 4kg/m3
A14: Densidad usada en estudio long term | B14: 1kg de lombriz por 10 kg de estiercol
B15: 0.1 | P15: =6.18/317 -> 0.019495268
A16: Peso de cada unidad promedio inicial | B16: https://www.researchgate.net/figure/Average-weight-of-E-eugeniae-in-the-different-substrates-over-the-experiment_fig1_281209563
A17: 1.2g
A19: Densidad en lombriz x m3
A20: =(4/0.0012)/0.8 -> 4166.6667
A22: Densidad usada en turrailba estudio sarmiento
A23: 15000 lombrices / m3
A24: =15/120 -> 0.125 | B24: kg lomb/estiercol
A26: Peso de la escenia foetida | B26: https://camjol.info/index.php/RCI/article/download/573/398/1821#:~:text=2.4%20Caracter%C3%ADsticas%20de%20la%20especie,su%20nombre%20(INTA%202005).
A27: 1g
A29: Densidad kg*m3
A30: =15000*0.001 -> 15
A33: Comparison between esenia y eudrilus
A34: https://onlinelibrary.wiley.com/doi/abs/10.1002/tqem.21852
A36: Eisenia foetida demonstrated a higher Corg mineralization (67.59%) compared to Eudrilus eugeniae, which attained 67.22%.
A38: Duracion de compostaje
B40: semans
A41: Estudio long term komakech | B41: 12
A42: turrialba | B42: 13
A43: turrialba recoleccion | B43: 2
A45: Solucion | B45: Se podria cuantificar esta ultima semana adinal que da sarmiento y las 2 posteriores de recoleccion utilizando la emision de GEI rportada por komakech nen la ultima semana y justificar que biologicamente el proceso ya llego a una etapa de mduracion
B46: Se podria suponer que ya se obtiene el producto final, colocando la frontera del sistema antes de la fase separacion y recoleccion de las lomb? No creo pror que es parte del sistema esta etapa
B47: Considerando que segun Sarm 'Por consiguiente, para cosecharlo todo se colocó a cada lado del producto terminado 20 kg de estiércol precompostado, con intermedio de dos capas de sarán para que las lombrices se desplazaran hacia la boñiga precompostada' entonces esta preocompostada ya se cuantifica, puesto que despues de anade a las pilas (no se sabe con cual d worm ensidad exacatemente), por otro lado el producto qu e van dejando atras las lombrices se pdria considerar la contiuacion de del vermicompostaje en su fase de maduracion, en cuanto a GEI se refiere.

Sheet Hoja2
B6: Nutriente | C6: Energía (MJ/kg) | D6: Total GEI (g/kg CO2-eq) | E6: Otras emisiones (mg/kg)
E7: NH1 | F7: PO4-3 | G7: SO2 | H7: Nox
B8: N | C8: 29,8 | D8: 2740 | E8: 0,06 | F8: 0,56 | G8: 4390 | H8: 4680
B9: P | C9: 30,5 | D9: 1670 | E9: 1460 | F9: 0,36 | G9: 38300 | H9: 18300

Sheet CH4 manure manag
A1: Calculo metano (se respetaran las unidades dadas en la eqs IPCC 2019)
A2: VS_sp
B3: VS_sp_rate | C3: TAM | D3: VS_sp
B4: 7.1 | C4: 500 | D4: =365*B4*C4/1000 -> 1295.75
A5: CH4
A6: N_tp | B6: 1
A7: VS_sp | B7: =D4 -> 1295.75
A8: AWMS-tsp | B8: 1
A9: EF_tsp
A10: Escenarios
A11: Pilas (dry lot) | B11: 1.3 | C11: =(B6*$B$7*$B$8*B11)/1000 -> 1.684475
A12: tirar al campo directo(daily spread) | B12: 0.4 | C12: =($B$6*$B$7*$B$8*B12)/1000 -> 0.5183
A13: tanques (si storage>1 mes, y poca agua) (liquid/slurry) | B13: =32.2 -> 32.2 | C13: =($B$6*$B$7*$B$8*B13)/1000 -> 41.72315
A14: Tratamiento aerobico | B14: N/A | C14: N/A
G94: From table 10.18 | H94: pag 73

Sheet CH4 Tier 2
A1: EF_t
A2: VS(t) | B2: 85.7432
A3: B_0(t) | B3: 0.24
A5: MCF% Escenarios
A6: Pilas (dry lot) | B6: 1.5
A7: tirar al campo directo(daily spread) | B7: 0.5
A8: tanques (si storage>=1 meses, y poca agua) (liquis/slurry) | B8: 13
A9: Tratamiento aerobico | B9: 0
A10: AWMS | B10: 1
A11: Resultados Escenarios
A12: Pilas (dry lot) | B12: =$B$2*365*$B$3*0.67*(B6/100)*$B$16 -> 75.486598
A13: tirar al campo directo(daily spread) | B13: =$B$2*365*$B$3*0.67*(B7/100)*$B$16 -> 25.162199
A14: tanques (si storage>=1 meses, y poca agua) (liquis/slurry) | B14: =$B$2*365*$B$3*0.67*(B8/100)*$B$16 -> 654.21719
A15: Tratamiento aerobico | B15: =$B$2*365*$B$3*0.67*(B9/100)*$B$16 -> 0
A16: AWMS | B16: 1

Sheet direct N2O manure manag
A1: Emisiones directas
A2: Emision N20 | P2: Para Nex
A4: N20-d(mm)
A5: TAM (Necesario por que Nex es dado por t de masa animal) | B5: 500
A6: N_(t,p) | B6: 1
A7: Nex_rate_(t,p) | B7: 1
A8: Nex_(t,p) | B8: 0.375
A9: N_cdg(s) | B9: 0
A10: AWMS | B10: 1
A11: EF_3(s)
A12: Escenarios | C12: Resultado
A13: Pilas (dry lot) | B13: 0.02 | C13: =(($B$6*$B$8*$B$10+B9)*B13)*44/28 -> 0.011785714
A14: tirar al campo directo(daily spread) | B14: 0 | C14: =(($B$6*$B$8*$B$10+B10)*B14)*44/28 -> 0
A15: tanques (si storage>1 meses, y poca agua) (liquis/slurry) | B15: 0.005 | C15: =(($B$6*$B$8*$B$10+B11)*B15)*44/28 -> 0.0029464286
A16: Tratamiento aerobico | B16: 0.01 | C16: =(($B$6*$B$8*$B$10+B12)*B16)*44/28 -> 0.0058928571

Sheet N volatilization 
A3: N_volatilization-MMS
A5: N_(t,p) | B5: 1
A6: Nex(t,p) | B6: ='direct N2O manure manag'!$B$8 -> 0.375
A7: N_cdg(s) | B7: 0
A8: AWMS | B8: 1
A9: Frac_gasms(t,s)
A10: Escenarios
A11: Pilas (dry lot) | B11: 0.3 | C11: =(($B$5*$B$6*$B$8)+$B$7)*B11 -> 0.1125
A12: tirar al campo directo(daily spread) | B12: 0.07 | C12: =(($B$5*$B$6*$B$8)+$B$7)*B12 -> 0.02625
A13: tanques (si storage>1 meses, y poca agua) (liquis/slurry) | B13: 0.1 | C13: =(($B$5*$B$6*$B$8)+$B$7)*B13 -> 0.0375
A14: Tratamiento aerobico | B14: 0.1 | C14: =(($B$5*$B$6*$B$8)+$B$7)*B14 -> 0.0375 | D14: Liquidslurrycovered

Sheet N lixiviado
A3: N_leaching_MMS
A5: N_(t,p) | B5: 1
A6: Nex(t,p) | B6: 0.375
A7: N_cdg(s) | B7: 0
A8: AWMS | B8: 1
A9: Frac_gasms(t,s)
A10: Escenarios
A11: Pilas (dry lot) | B11: 0.035 | C11: =(($B$5*$B$6*$B$8)+$B$7)*B11 -> 0.013125
A12: tirar al campo directo(daily spread) | B12: 0 | C12: =(($B$5*$B$6*$B$8)+$B$7)*B12 -> 0
A13: tanques (si storage>1 meses, y poca agua) (liquis/slurry) | B13: 0 | C13: =(($B$5*$B$6*$B$8)+$B$7)*B13 -> 0
A14: Tratamiento aerobico | B14: 0 | C14: =(($B$5*$B$6*$B$8)+$B$7)*B14 -> 0

Sheet N20 inidrecto
A1: N2O_g(mm)
A2: N_volatilization-MMS | B2: Frac_gasms(t,s)
A3: ='N volatilization '!A10 -> Escenarios | B3: ='N volatilization '!B10 -> 0 | C3: ='N volatilization '!C10 -> 0
A4: ='N volatilization '!A11 -> Pilas (dry lot) | B4: ='N volatilization '!B11 -> 0.3 | C4: ='N volatilization '!C11 -> 0.1125
A5: ='N volatilization '!A12 -> tirar al campo directo(daily spread) | B5: ='N volatilization '!B12 -> 0.07 | C5: ='N volatilization '!C12 -> 0.02625
A6: ='N volatilization '!A13 -> tanques (si storage>1 meses, y poca agua) (liquis/slurry) | B6: ='N volatilization '!B13 -> 0.1 | C6: ='N volatilization '!C13 -> 0.0375
A7: Tratamiento aerobico | B7: ='N volatilization '!B14 -> 0.1 | C7: ='N volatilization '!C14 -> 0.0375
A8: EF4 | B8: 0.014
A9: Escenarios Resultado
A10: Pilas (dry lot) | B10: =C4*$B$8*44/28 -> 0.002475
A11: tirar al campo directo(daily spread) | B11: =C5*$B$8*44/28 -> 0.0005775
A12: tanques (si storage>5 meses, y poca agua) (liquis/slurry) | B12: =C6*$B$8*44/28 -> 0.000825
A13: Tratamiento aerobico | B13: =C7*$B$8*44/28 -> 0.000825
A28: N2O_l(mm)
A29: N_leaching_MMS
A30: ='N lixiviado'!A10 -> Escenarios | B30: ='N lixiviado'!B10 -> 0 | C30: ='N lixiviado'!C10 -> 0
A31: ='N lixiviado'!A11 -> Pilas (dry lot) | B31: ='N lixiviado'!B11 -> 0.035 | C31: ='N lixiviado'!C11 -> 0.013125
A32: ='N lixiviado'!A12 -> tirar al campo directo(daily spread) | B32: ='N lixiviado'!B12 -> 0 | C32: ='N lixiviado'!C12 -> 0
A33: ='N lixiviado'!A13 -> tanques (si storage>1 meses, y poca agua) (liquis/slurry) | B33: ='N lixiviado'!B13 -> 0 | C33: ='N lixiviado'!C13 -> 0
A34: Tratamiento aerobico | B34: ='N lixiviado'!B14 -> 0 | C34: ='N lixiviado'!C14 -> 0
A35: EF_5 | B35: 0.011
A36: Escenarios Resultado
A37: Pilas (dry lot) | B37: =C31*$B$35*44/28 -> 0.000226875
A38: tirar al campo directo(daily spread) | B38: =C32*$B$35*44/28 -> 0
A39: tanques (si storage>1 meses, y poca agua) (liquis/slurry) | B39: =C33*$B$35*44/28 -> 0
A40: Tratamiento aerobico | B40: =C34*$B$35*44/28 -> 0

Sheet Molecular mass calc
A1: O | B1: 16
A2: N | B2: 14.007
A3: H | B3: 1.008
A4: NH3
A5: =(1*B2+3*B3)/B2 -> 1.2158921 | B5: =17/14 -> 1.2142857
A7: N2O
A8: =(B2*2+B1)/(B2*2) -> 1.571143 | B8: =44/28 -> 1.5714286
A12: NO3
A13: =(B2+B1*3)/B2 -> 4.426858 | B13: =31/7 -> 4.4285714

Sheet suelo_N20directo
A1: Sys | B1: N20_N | C1: N20
A2: daily_spread | B2: =B7*B$5 -> 0.0020925 | C2: =B2*48/28 -> 0.0035871429
A3: tanques (si storage>1 meses, y poca agua) (liquis/slurry) | B3: =B8*B$5 -> 0.00198 | C3: =B3*48/28 -> 0.0033942857
A4: Tratamiento aerobico | B4: =B9*B$5 -> 0.001935 | C4: =B4*48/28 -> 0.0033171429
A5: EF1 | B5: 0.006
A6: Fon | C6: Simbolico pero mismo valor
A7: daily_spread | B7: =B11 -> 0.34875
A8: tanques (si storage>1 meses, y poca agua) (liquis/slurry) | B8: =B12 -> 0.33
A9: Tratamiento aerobico | B9: =B13 -> 0.3225
A10: N_MMS_avb
A11: daily_spread | B11: =(B$14*B$15+B$16)*(1-B18) -> 0.34875
A12: tanques (si storage>1 meses, y poca agua) (liquis/slurry) | B12: =(B$14*B$15+B$16)*(1-B19) -> 0.33
A13: Tratamiento aerobico | B13: =(B$14*B$15+B$16)*(1-B20) -> 0.3225
A14: Nex | B14: ='direct N2O manure manag'!B8 -> 0.375
A15: AWMS_ts | B15: 1
A16: N_cdg | B16: 0
A17: Frac_LossMS_TS
A18: daily_spread | B18: ='direct N2O manure manag'!B14+'N volatilization '!B12+'N lixiviado'!B12 + 3*'direct N2O manure manag'!B14 -> 0.07
A19: tanques (si storage>1 meses, y poca agua) (liquis/slurry) | B19: ='direct N2O manure manag'!B15+'N volatilization '!B13+'N lixiviado'!B13 + 3*'direct N2O manure manag'!B15 -> 0.12
A20: Tratamiento aerobico | B20: ='direct N2O manure manag'!B16+'N volatilization '!B14+'N lixiviado'!B14 + 3*'direct N2O manure manag'!B16 -> 0.14

Sheet suelo_N20indirecto
A1: Leaching
A2: N2OL-N | C2: N20
A3: daily_spread | B3: =B8*B$11*B$6 -> 0.0009207 | C3: =B3*48/28 -> 0.0015783429
A4: tanques (si storage>1 meses, y poca agua) (liquis/slurry) | B4: =B9*B$11*B$6 -> 0.0008712 | C4: =B4*48/28 -> 0.0014934857
A5: Tratamiento aerobico | B5: =B10*B$11*B$6 -> 0.0008514 | C5: =B5*48/28 -> 0.0014595429
A6: EF5 | B6: 0.011
A7: Fon
A8: daily_spread | B8: =suelo_N20directo!B7 -> 0.34875
A9: tanques (si storage>1 meses, y poca agua) (liquis/slurry) | B9: =suelo_N20directo!B8 -> 0.33
A10: Tratamiento aerobico | B10: =suelo_N20directo!B9 -> 0.3225
A11: Frac_LEACH-H | B11: 0.24
A14: ATD
A15: N2OATD-N
A16: daily_spread | B16: =B21*B$24*B$19 -> 0.001025325
A17: tanques (si storage>1 meses, y poca agua) (liquis/slurry) | B17: =B22*B$24*B$19 -> 0.0009702
A18: Tratamiento aerobico | B18: =B23*B$24*B$19 -> 0.00094815
A19: EF4 | B19: 0.014
A20: Fon
A21: daily_spread | B21: =B8 -> 0.34875
A22: tanques (si storage>1 meses, y poca agua) (liquis/slurry) | B22: =B9 -> 0.33
A23: Tratamiento aerobico | B23: =B10 -> 0.3225
A24: Frac_GASM | B24: 0.21

Sheet Summary (3)
A2: Tabla 1: Factores de emision de los principales ítems/actividades incluidos en el inventario en cada etapa del tratamiento por escenario
A3: Items y actividades | B3: Escenario | C3: Etapa | D3: Tipo de emisión | E3: Categoria de impacto | F3: Compuesto | G3: Cantidad | H3: Unidad | I3: Referencia
A4: Estiércol poducido | B4: AB | C4: N/A | D4: N/A | E4: N/A | F4: N/A | G4: 25 | H4: kg estiércol en base humeda UG -1dia -1 | I4: (Salazar, 2012)
A5: % promedio de materia seca en el estiércol del ganado bovino lechero | B5: A | C5: N/A | D5: N/A | E5: N/A | F5: N/A | G5: 13.6 | H5: % | I5: (Callejo, 2020)
A6: Emisiones del estiércol durante el lombricompostaje | B6: A | C6: lombricompostaje | D6: Directa | E6: calentamiento global | F6: CH4 | G6: =7.6*365/(12*7) -> 33.02381 | H6: g kg-1 estiércol en base seca año-1 | I6: (Jjagwe et al., 2019)
F7: N2O | G7: =0.00003943*365/(12*7) -> 0.00017133274 | H7: g kg-1 estiércol en base seca año-1 | I7: (Jjagwe et al., 2019)
D8: Indirecta | E8: calentamiento global y eutrofización | F8: N lixiviado | G8: =G16 -> 0.013125 | H8: kg UG -1 año -1 | I8: (IPCC, 2019)
F9: N volatilizado | G9: =0 -> 0 | H9: kg UG -1 año -1 | I9: (Jjagwe et al., 2019)
E10: calentamiento global | F10: N2O lixiviado | G10: =G18 -> 0.000226875 | H10: kg UG -1 año -1 | I10: (IPCC, 2019)
F11: N2O volatilizado | G11: =0 -> 0 | H11: kg UG -1 año -1 | I11: (IPCC, 2019)
E12: eutrofización | F12: NH3 | G12: =(G9-G11)*0.5+(G8-G10)*0.5 -> 0.0064490625 | H12: g kg-1 estiércol en base seca año-1 | I12: (IPCC, 2019)
F13: NO3- | G13: =(G8-G10)*0.5+(G9-G11)*0.5 -> 0.0064490625 | H13: kg UG -1 año -1 | I13: (IPCC, 2019)
A14: Emisiones del estiércol gestionado mediante ‘lote seco’ | B14: A | C14: Precomposteo | D14: Directa | E14: calentamiento global | F14: CH4 | G14: ='CH4 Tier 2'!B12 -> 75.486598 | H14: kg UG -1 año -1 | I14: (IPCC, 2019)
F15: N2O | G15: ='direct N2O manure manag'!C13 -> 0.011785714 | H15: kg UG -1 año -1 | I15: (IPCC, 2019)
D16: Indirecta | E16: calentamiento global y eutrofización | F16: N lixiviado | G16: ='N lixiviado'!C11 -> 0.013125 | H16: kg UG -1 año -1 | I16: (IPCC, 2019)
F17: N volatilizado | G17: ='N volatilization '!C11 -> 0.1125 | H17: kg UG -1 año -1 | I17: (IPCC, 2019)
E18: calentamiento global | F18: N2O lixiviado | G18: ='N20 inidrecto'!B37 -> 0.000226875 | H18: kg UG -1 año -1 | I18: (IPCC, 2019)
F19: N2O volatilizado | G19: ='N20 inidrecto'!B10 -> 0.002475 | H19: kg UG -1 año -1 | I19: (IPCC, 2019)
E20: eutrofización | F20: NH3 | G20: =(G16-G18)*0.5+(G17-G19)*0.5 -> 0.061461562 | H20: kg UG -1 año -1 | I20: (IPCC, 2019)
F21: NO3- | G21: =(G16-G18)*0.5+(G17-G19)*0.5 -> 0.061461562 | H21: kg UG -1 año -1 | I21: (IPCC, 2019)
A22: Emisiones del estiércol gestionado mediante ‘tratamiento aerobico’ | B22: AB | C22: Almacenamiento de estiércol con agua (aguas verdes o purines) | D22: Directa | E22: calentamiento global | F22: CH4 | G22: ='CH4 Tier 2'!B15 -> 0 | H22: kg UG -1 año -1 | I22: (IPCC, 2019)
F23: N2O | G23: ='direct N2O manure manag'!C16 -> 0.0058928571 | H23: kg UG -1 año -1 | I23: (IPCC, 2019)
D24: Indirecta | E24: calentamiento global y eutrofización | F24: N lixiviado | G24: ='N lixiviado'!C14 -> 0 | H24: kg UG -1 año -1 | I24: (IPCC, 2019)
F25: N volatilizado | G25: ='N volatilization '!C14 -> 0.0375 | H25: kg UG -1 año -1 | I25: (IPCC, 2019)
E26: calentamiento global | F26: N2O lixiviado | G26: ='N20 inidrecto'!B40 -> 0 | H26: kg UG -1 año -1 | I26: (IPCC, 2019)
F27: N2O volatilizado | G27: ='N20 inidrecto'!B13 -> 0.000825 | H27: kg UG -1 año -1 | I27: (IPCC, 2019)
E28: eutrofización | F28: NH3 | G28: =(G24-G26)*0.5+(G25-G27)*0.5 -> 0.0183375 | H28: kg UG -1 año -1 | I28: (IPCC, 2019)
F29: NO3- | G29: =(G24-G26)*0.5+(G25-G27)*0.5 -> 0.0183375 | H29: kg UG -1 año -1 | I29: (IPCC, 2019)
A30: Emisiones del suelo gestionado cuando se añade el estiércol previamente tratado mediante 'tratamiento aerobico' | B30: AB | C30: Aplicación en campo de aguas verdes o purines | D30: Directa | E30: calentamiento global | F30: N2O | G30: =suelo_N20directo!C4 -> 0.0033171429 | H30: kg UG -1 año -1 | I30: (IPCC, 2019)
D31: Indirecta | E31: calentamiento global y eutrofización | F31: N lixiviado | G31: =suelo_N20indirecto!C5/suelo_N20indirecto!B6 -> 0.13268571 | H31: kg UG -1 año -1 | I31: (IPCC, 2019)
F32: N volatilizado | G32: =suelo_N20indirecto!B18/suelo_N20indirecto!B19 -> 0.067725 | H32: kg UG -1 año -1 | I32: (IPCC, 2019)
E33: calentamiento global | F33: N2O lixiviado | G33: =suelo_N20indirecto!C5 -> 0.0014595429 | H33: kg UG -1 año -1 | I33: (IPCC, 2019)
F34: N2O volatilizado | G34: =suelo_N20indirecto!B18 -> 0.00094815 | H34: kg UG -1 año -1 | I34: (IPCC, 2019)
E35: eutrofización | F35: NH3 | G35: =(G31-G33)*0.5+(G32-G34)*0.5 -> 0.099001511 | H35: kg UG -1 año -1 | I35: (IPCC, 2019)
F36: NO3- | G36: =(G31-G33)*0.5+(G32-G34)*0.5 -> 0.099001511 | H36: kg UG -1 año -1 | I36: (IPCC, 2019)

Sheet GWP and EPP
A2: Compuesto | B2: Equivalentes de CO2 | C2: Equivalentes de PO4³⁻-eq | D2: Fuente
A3: CH4 | B3: 21 | C3: N/A | D3: (IMN, 2021)
A4: N2O | B4: 310 | C4: N/A
A5: NH3 | B5: N/A | C5: 0,35 | D5: (Vallejo, 2004)
A6: NO3- | B6: N/A | C6: 0,095

Sheet TS avg
B2: Total | C2: TS | D2: %
A3: 1 | B3: 6 | C3: 0.8 | D3: =C3/B3 -> 0.13333333
A4: 2 | B4: 10 | C4: 1.35 | D4: =C4/B4 -> 0.135
A5: 3 | B5: 20 | C5: 2.7 | D5: =C5/B5 -> 0.135
A6: 4 | B6: 40 | C6: 5.5 | D6: =C6/B6 -> 0.1375
A7: 5 | B7: 55 | C7: 7.6 | D7: =C7/B7 -> 0.13818182
C8: avg | D8: =AVERAGE(D3:D7)*100 -> 13.580303
C9: meida | D9: =MEDIAN(D3:D7)*100 -> 13.5
A10: From | B10: https://oa.upm.es/cgi/export/65177/

Sheet Summary
A2: Tabla 1: Factores de emision de los principales ítems/actividades incluidos en el inventario en cada etapa del tratamiento por escenario
A3: Items y actividades | B3: Escenario | C3: Etapa | D3: Tipo de emisión | E3: Categoria de impacto | F3: Compuesto | G3: Cantidad | H3: Unidad | I3: Referencia
A4: Estiércol poducido | B4: AB | C4: Ingreso al sistema | D4: N/A | E4: N/A | F4: N/A | G4: 25 | H4: kg estiércol en base humeda UG -1dia -1 | I4: (Salazar, 2012)
A5: % promedio de materia seca en el estiércol del ganado bovino lechero | B5: A | C5: Ingreso al sistema | D5: N/A | E5: N/A | F5: N/A | G5: 13.6 | H5: % | I5: (Callejo, 2020)
A6: Emisiones del estiércol durante el lombricompostaje | B6: A | C6: Durante lombricompostaje | D6: Directa | E6: calentamiento global | F6: CH4 | G6: =7.6*365/(12*7) -> 33.02381 | H6: g kg-1 estiércol en base seca año-1 | I6: (Jjagwe et al., 2019)
F7: N2O | G7: =0.00003943*365/(12*7) -> 0.00017133274 | H7: g kg-1 estiércol en base seca año-1 | I7: (Jjagwe et al., 2019)
D8: Indirecta | E8: calentamiento global y eutrofización | F8: N lixiviado | G8: =G16 -> 0.013125 | H8: kg UG -1 año -1 | I8: (IPCC, 2019)
F9: N volatilizado | G9: =0 -> 0 | H9: kg UG -1 año -1 | I9: (Jjagwe et al., 2019)
E10: calentamiento global | F10: N2O lixiviado | G10: =G18 -> 0.000226875 | H10: kg UG -1 año -1 | I10: (IPCC, 2019)
F11: N2O volatilizado | G11: =0 -> 0 | H11: kg UG -1 año -1 | I11: (IPCC, 2019)
E12: eutrofización | F12: NH3 | G12: =(G9-G11)*0.5+(G8-G10)*0.5 -> 0.0064490625 | H12: g kg-1 estiércol en base seca año-1 | I12: (IPCC, 2019)
F13: NO3- | G13: =(G8-G10)*0.5+(G9-G11)*0.5 -> 0.0064490625 | H13: kg UG -1 año -1 | I13: (IPCC, 2019)
A14: Emisiones del estiércol tratado mediante ‘lote seco’ | B14: A | C14: Precomposteo en pilas | D14: Directa | E14: calentamiento global | F14: CH4 | G14: ='CH4 Tier 2'!B12 -> 75.486598 | H14: kg UG -1 año -1 | I14: (IPCC, 2019)
F15: N2O | G15: ='direct N2O manure manag'!C13 -> 0.011785714 | H15: kg UG -1 año -1 | I15: (IPCC, 2019)
D16: Indirecta | E16: calentamiento global y eutrofización | F16: N lixiviado | G16: ='N lixiviado'!C11 -> 0.013125 | H16: kg UG -1 año -1 | I16: (IPCC, 2019)
F17: N volatilizado | G17: ='N volatilization '!C11 -> 0.1125 | H17: kg UG -1 año -1 | I17: (IPCC, 2019)
E18: calentamiento global | F18: N2O lixiviado | G18: ='N20 inidrecto'!B37 -> 0.000226875 | H18: kg UG -1 año -1 | I18: (IPCC, 2019)
F19: N2O volatilizado | G19: ='N20 inidrecto'!B10 -> 0.002475 | H19: kg UG -1 año -1 | I19: (IPCC, 2019)
E20: eutrofización | F20: NH3 | G20: =(G16-G18)*0.5+(G17-G19)*0.5 -> 0.061461562 | H20: kg UG -1 año -1 | I20: (IPCC, 2019)
F21: NO3- | G21: =(G16-G18)*0.5+(G17-G19)*0.5 -> 0.061461562 | H21: kg UG -1 año -1 | I21: (IPCC, 2019)
A22: Emisiones del estiércol tratado mediante ‘propagación diaria’ | B22: A | C22: Aplicación manual de estiercol fresco en campos | D22: Directa | E22: calentamiento global | F22: CH4 | G22: ='CH4 manure manag'!C12 -> 0.5183 | H22: kg UG -1 año -1 | I22: (IPCC, 2019)
F23: N2O | G23: ='CH4 Tier 2'!B13 -> 25.162199 | H23: kg UG -1 año -1 | I23: (IPCC, 2019)
D24: Indirecta | E24: calentamiento global y eutrofización | F24: N lixiviado | G24: ='N lixiviado'!C12 -> 0 | H24: kg UG -1 año -1 | I24: (IPCC, 2019)
F25: N volatilizado | G25: ='N volatilization '!C12 -> 0.02625 | H25: kg UG -1 año -1 | I25: (IPCC, 2019)
E26: calentamiento global | F26: N2O lixiviado | G26: ='N20 inidrecto'!B38 -> 0 | H26: kg UG -1 año -1 | I26: (IPCC, 2019)
F27: N2O volatilizado | G27: ='N volatilization '!B11 -> 0.3 | H27: kg UG -1 año -1 | I27: (IPCC, 2019)
E28: eutrofización | F28: NH3 | G28: =(G24-G26)*0.5+(G25-G27)*0.5 -> -0.136875 | H28: kg UG -1 año -2 | I28: (IPCC, 2019)
F29: NO3- | G29: =(G24-G26)*0.5+(G25-G27)*0.5 -> -0.136875 | H29: kg UG -1 año -3 | I29: (IPCC, 2019)
A30: Emisiones del estiércol tratado mediante ‘estiércol líquido’ | B30: B | C30: Almacenamiento en tanque | D30: Directa | E30: calentamiento global | F30: CH4 | G30: ='CH4 Tier 2'!B14 -> 654.21719 | H30: kg UG -1 año -1 | I30: (IPCC, 2019)
F31: N2O | G31: ='direct N2O manure manag'!C15 -> 0.0029464286 | H31: kg UG -1 año -1 | I31: (IPCC, 2019)
D32: Indirecta | E32: calentamiento global y eutrofización | F32: N lixiviado | G32: ='N lixiviado'!C13 -> 0 | H32: kg UG -1 año -1 | I32: (IPCC, 2019)
F33: N volatilizado | G33: ='N volatilization '!C13 -> 0.0375 | H33: kg UG -1 año -1 | I33: (IPCC, 2019)
E34: calentamiento global | F34: N2O lixiviado | G34: ='N20 inidrecto'!B39 -> 0 | H34: kg UG -1 año -1 | I34: (IPCC, 2019)
F35: N2O volatilizado | G35: ='N20 inidrecto'!B12 -> 0.000825 | H35: kg UG -1 año -1 | I35: (IPCC, 2019)
E36: eutrofización | F36: NH3 | G36: =(G32-G34)*0.5+(G33-G35)*0.5 -> 0.0183375 | H36: kg UG -1 año -1 | I36: (IPCC, 2019)
F37: NO3- | G37: =(G32-G34)*0.5+(G33-G35)*0.5 -> 0.0183375 | H37: kg UG -1 año -1 | I37: (IPCC, 2019)
A38: Emisiones del estiércol tratado mediante ‘tratamiento aerobico’ | B38: B | C38: Almacenamiento en tanque | D38: Directa | E38: calentamiento global | F38: CH4 | G38: ='CH4 Tier 2'!B15 -> 0 | H38: kg UG -1 año -1 | I38: (IPCC, 2019)
F39: N2O | G39: ='direct N2O manure manag'!C16 -> 0.0058928571 | H39: kg UG -1 año -1 | I39: (IPCC, 2019)
D40: Indirecta | E40: calentamiento global y eutrofización | F40: N lixiviado | G40: ='N lixiviado'!C14 -> 0 | H40: kg UG -1 año -1 | I40: (IPCC, 2019)
F41: N volatilizado | G41: ='N volatilization '!C14 -> 0.0375 | H41: kg UG -1 año -1 | I41: (IPCC, 2019)
...

Sheet Summary (2)
A2: Tabla 1: Factores de emision de los principales ítems/actividades incluidos en el inventario en cada etapa del tratamiento por escenario
A3: Items y actividades | B3: Escenario | C3: Etapa | D3: Tipo de emisión | E3: Categoria de impacto | F3: Compuesto | G3: Cantidad | H3: Unidad | I3: Referencia
A4: Estiércol poducido | B4: AB | C4: Ingreso al sistema | D4: N/A | E4: N/A | F4: N/A | G4: 25 | H4: kg estiércol en base humeda UG -1dia -1 | I4: (Salazar, 2012)
A5: % promedio de materia seca en el estiércol del ganado bovino lechero | B5: A | C5: Ingreso al sistema | D5: N/A | E5: N/A | F5: N/A | G5: 13.6 | H5: % | I5: (Callejo, 2020)
A6: Emisiones del estiércol durante el lombricompostaje | B6: A | C6: Durante lombricompostaje | D6: Directa | E6: calentamiento global | F6: CH4 | G6: =7.6*365/(12*7) -> 33.02381 | H6: g kg-1 estiércol en base seca año-1 | I6: (Jjagwe et al., 2019)
F7: N2O | G7: =0.00003943*365/(12*7) -> 0.00017133274 | H7: g kg-1 estiércol en base seca año-1 | I7: (Jjagwe et al., 2019)
D8: Indirecta | E8: calentamiento global y eutrofización | F8: N lixiviado | G8: =G16 -> 0.013125 | H8: kg UG -1 año -1 | I8: (IPCC, 2019)
F9: N volatilizado | G9: =0 -> 0 | H9: kg UG -1 año -1 | I9: (Jjagwe et al., 2019)
E10: calentamiento global | F10: N2O lixiviado | G10: =G18 -> 0.000226875 | H10: kg UG -1 año -1 | I10: (IPCC, 2019)
F11: N2O volatilizado | G11: =0 -> 0 | H11: kg UG -1 año -1 | I11: (IPCC, 2019)
E12: eutrofización | F12: NH3 | G12: =(G9-G11)*0.5+(G8-G10)*0.5 -> 0.0064490625 | H12: g kg-1 estiércol en base seca año-1 | I12: (IPCC, 2019)
F13: NO3- | G13: =(G8-G10)*0.5+(G9-G11)*0.5 -> 0.0064490625 | H13: kg UG -1 año -1 | I13: (IPCC, 2019)
A14: Emisiones del estiércol tratado mediante ‘lote seco’ | B14: A | C14: Precomposteo en pilas | D14: Directa | E14: calentamiento global | F14: CH4 | G14: ='CH4 Tier 2'!B12 -> 75.486598 | H14: kg UG -1 año -1 | I14: (IPCC, 2019)
F15: N2O | G15: ='direct N2O manure manag'!C13 -> 0.011785714 | H15: kg UG -1 año -1 | I15: (IPCC, 2019)
D16: Indirecta | E16: calentamiento global y eutrofización | F16: N lixiviado | G16: ='N lixiviado'!C11 -> 0.013125 | H16: kg UG -1 año -1 | I16: (IPCC, 2019)
F17: N volatilizado | G17: ='N volatilization '!C11 -> 0.1125 | H17: kg UG -1 año -1 | I17: (IPCC, 2019)
E18: calentamiento global | F18: N2O lixiviado | G18: ='N20 inidrecto'!B37 -> 0.000226875 | H18: kg UG -1 año -1 | I18: (IPCC, 2019)
F19: N2O volatilizado | G19: ='N20 inidrecto'!B10 -> 0.002475 | H19: kg UG -1 año -1 | I19: (IPCC, 2019)
E20: eutrofización | F20: NH3 | G20: =(G16-G18)*0.5+(G17-G19)*0.5 -> 0.061461562 | H20: kg UG -1 año -1 | I20: (IPCC, 2019)
F21: NO3- | G21: =(G16-G18)*0.5+(G17-G19)*0.5 -> 0.061461562 | H21: kg UG -1 año -1 | I21: (IPCC, 2019)
A22: Emisiones del estiércol tratado mediante ‘propagación diaria’ | B22: A | C22: Aplicación manual de estiercol fresco en campos | D22: Directa | E22: calentamiento global | F22: CH4 | G22: ='CH4 manure manag'!C12 -> 0.5183 | H22: kg UG -1 año -1 | I22: (IPCC, 2019)
F23: N2O | G23: ='CH4 Tier 2'!B13 -> 25.162199 | H23: kg UG -1 año -1 | I23: (IPCC, 2019)
D24: Indirecta | E24: calentamiento global y eutrofización | F24: N lixiviado | G24: ='N lixiviado'!C12 -> 0 | H24: kg UG -1 año -1 | I24: (IPCC, 2019)
F25: N volatilizado | G25: ='N volatilization '!C12 -> 0.02625 | H25: kg UG -1 año -1 | I25: (IPCC, 2019)
E26: calentamiento global | F26: N2O lixiviado | G26: ='N20 inidrecto'!B38 -> 0 | H26: kg UG -1 año -1 | I26: (IPCC, 2019)
F27: N2O volatilizado | G27: ='N volatilization '!B11 -> 0.3 | H27: kg UG -1 año -1 | I27: (IPCC, 2019)
E28: eutrofización | F28: NH3 | G28: =(G24-G26)*0.5+(G25-G27)*0.5 -> -0.136875 | H28: kg UG -1 año -2 | I28: (IPCC, 2019)
F29: NO3- | G29: =(G24-G26)*0.5+(G25-G27)*0.5 -> -0.136875 | H29: kg UG -1 año -3 | I29: (IPCC, 2019)
A30: Emisiones del estiércol tratado mediante ‘estiércol líquido’ | B30: B | C30: Almacenamiento en tanque | D30: Directa | E30: calentamiento global | F30: CH4 | G30: ='CH4 Tier 2'!B14 -> 654.21719 | H30: kg UG -1 año -1 | I30: (IPCC, 2019)
F31: N2O | G31: ='direct N2O manure manag'!C15 -> 0.0029464286 | H31: kg UG -1 año -1 | I31: (IPCC, 2019)
D32: Indirecta | E32: calentamiento global y eutrofización | F32: N lixiviado | G32: ='N lixiviado'!C13 -> 0 | H32: kg UG -1 año -1 | I32: (IPCC, 2019)
F33: N volatilizado | G33: ='N volatilization '!C13 -> 0.0375 | H33: kg UG -1 año -1 | I33: (IPCC, 2019)
E34: calentamiento global | F34: N2O lixiviado | G34: ='N20 inidrecto'!B39 -> 0 | H34: kg UG -1 año -1 | I34: (IPCC, 2019)
F35: N2O volatilizado | G35: ='N20 inidrecto'!B12 -> 0.000825 | H35: kg UG -1 año -1 | I35: (IPCC, 2019)
E36: eutrofización | F36: NH3 | G36: =(G32-G34)*0.5+(G33-G35)*0.5 -> 0.0183375 | H36: kg UG -1 año -1 | I36: (IPCC, 2019)
F37: NO3- | G37: =(G32-G34)*0.5+(G33-G35)*0.5 -> 0.0183375 | H37: kg UG -1 año -1 | I37: (IPCC, 2019)
A38: Emisiones del estiércol tratado mediante ‘tratamiento aerobico’ | B38: AB | C38: Almacenamiento de estiérco con agua en tanque | D38: Directa | E38: calentamiento global | F38: CH4 | G38: ='CH4 Tier 2'!B15 -> 0 | H38: kg UG -1 año -1 | I38: (IPCC, 2019)
F39: N2O | G39: ='direct N2O manure manag'!C16 -> 0.0058928571 | H39: kg UG -1 año -1 | I39: (IPCC, 2019)
D40: Indirecta | E40: calentamiento global y eutrofización | F40: N lixiviado | G40: ='N lixiviado'!C14 -> 0 | H40: kg UG -1 año -1 | I40: (IPCC, 2019)
F41: N volatilizado | G41: ='N volatilization '!C14 -> 0.0375 | H41: kg UG -1 año -1 | I41: (IPCC, 2019)
...

Sheet Hoja4

Sheet Hoja5
